Workbook

Sheet аннотация

Sheet stations
A1: date | B1: station | C1: coord_lat | D1: coord_lon | E1: sample | F1: sample_id | G1: sample_area | H1: mesh_size | I1: salinity | J1: fucoids_m | K1: field_note
A2: 45841 | B2: 34 | C2: 64.34636 | D2: 37.30762 | E2: 3 | F2: ОН34_3 | I2: 25 | J2: 264.3 | K2: рядом с каменистой грядой с фукоидами, грунт сходный с ОН32, указан вес фукоидов
A3: 45841 | B3: 34 | C3: 64.34636 | D3: 37.30762 | E3: 2 | F3: ОН34_2 | I3: 25 | J3: 67 | K3: рядом с каменистой грядой с фукоидами, грунт сходный с ОН32, указан вес фукоидов
A4: 45841 | B4: 34 | C4: 64.34636 | D4: 37.30762
A5: 45841 | B5: 32 | C5: 64.34579 | D5: 37.31017 | I5: 32 | K5: лагуна, ограниченная каменистой грядой с фукоидами, Entreomorpha, Crangon
A6: 45840 | B6: 31 | C6: 64.34278 | D6: 37.32664 | I6: 24.5 | K6: в пределах рамки 31_3 - пескожил.

Sheet NB
A1: station | B1: sample | C1: station_name | D1: size_code | E1: taxon_name | F1: species_code | G1: density | H1: biomass | I1: added_by_user | J1: notes
A2: 8 | B2: 3 | C2: ОН8_3 | D2: NA | E2: Macoma balthica | F2: =VLOOKUP(E2,species_list!A$2:B$1194,2,FALSE) -> 435 | H2: 11.456 | I2: Аристов | J2: Alexeeva_onega25.pdf(11), Poloskin-2_01.jpg, (0.5)
A3: 8 | B3: 3 | C3: ОН8_3 | D3: NA | E3: Alita virens | F3: =VLOOKUP(E3,species_list!A$2:B$1194,2,FALSE) -> 789 | G3: 2 | H3: 0.025 | I3: Аристов | J3: Alexeeva_onega25.pdf(11), Poloskin-2_01.jpg, (0.5)
A4: 8 | B4: 3 | C4: ОН8_3 | D4: NA | E4: Tubifex costatus | F4: =VLOOKUP(E4,species_list!A$2:B$1194,2,FALSE) -> 828 | G4: 3 | H4: 0.005 | I4: Аристов | J4: Alexeeva_onega25.pdf(11), Poloskin-2_01.jpg, (0.5)
A5: 8 | B5: 3 | C5: ОН8_3 | D5: NA | E5: Hydrobia ventrosa | F5: =VLOOKUP(E5,species_list!A$2:B$1194,2,FALSE) -> 376 | G5: 72 | H5: 0.372 | I5: Аристов | J5: Alexeeva_onega25.pdf(11), Poloskin-2_01.jpg, (0.5), рассчетные значения, суммарно 339x3,462
A6: 8 | B6: 3 | C6: ОН8_3 | D6: NA | E6: Hydrobia ulvae | F6: =VLOOKUP(E6,species_list!A$2:B$1194,2,FALSE) -> 375 | G6: 407 | H6: 3.438 | I6: Аристов | J6: Alexeeva_onega25.pdf(11), Poloskin-2_01.jpg, (0.5), рассчетные значения, суммарно 339x3,463
A7: 8 | B7: 3 | C7: ОН8_3 | D7: NA | E7: Hydrobia sp. | F7: =VLOOKUP(E7,species_list!A$2:B$1194,2,FALSE) -> #N/A | G7: 51 | H7: 0.027 | I7: Манылова | J7: Alexeeva_onega25.pdf(11), Poloskin-2_01.jpg, (0.5)
A8: 8 | B8: 3 | C8: ОН8_3 | D8: NA | E8: Nereis sp. | F8: =VLOOKUP(E8,species_list!A$2:B$1194,2,FALSE) -> 788 | G8: 1 | H8: 0.001 | I8: Манылова | J8: Alexeeva_onega25.pdf(11), Poloskin-2_01.jpg, (0.5)
A9: 8 | B9: 3 | C9: ОН8_3 | D9: NA | E9: Nephthys minuta | F9: =VLOOKUP(E9,species_list!A$2:B$1194,2,FALSE) -> 784 | G9: 1 | H9: 0.001 | I9: Манылова | J9: Alexeeva_onega25.pdf(11), Poloskin-2_01.jpg, (0.5)
A10: 8 | B10: 2 | C10: ОН8_2 | D10: NA | E10: Macoma balthica | F10: =VLOOKUP(E10,species_list!A$2:B$1194,2,FALSE) -> 435 | G10: 24 | H10: 6.895 | I10: Аристов | J10: Alexeeva_onega25.pdf(12), Poloskin-2_01.jpg, (0.5)
A11: 8 | B11: 2 | C11: ОН8_2 | D11: NA | E11: Mya arenaria | F11: =VLOOKUP(E11,species_list!A$2:B$1194,2,FALSE) -> 440 | G11: 3 | H11: 1.199 | I11: Аристов | J11: Alexeeva_onega25.pdf(12), Poloskin-2_01.jpg, (0.5)
A12: 8 | B12: 2 | C12: ОН8_2 | D12: NA | E12: Hydrobia ulvae | F12: =VLOOKUP(E12,species_list!A$2:B$1194,2,FALSE) -> 375 | G12: 549 | H12: 1.266 | I12: Аристов | J12: Alexeeva_onega25.pdf(12), рассчетные значения, суммарно 470x1,087
A13: 8 | B13: 2 | C13: ОН8_2 | D13: NA | E13: Hydrobia ventrosa | F13: =VLOOKUP(E13,species_list!A$2:B$1194,2,FALSE) -> 376 | G13: 40 | H13: 0.065 | I13: Аристов | J13: Alexeeva_onega25.pdf(12), рассчетные значения, суммарно 470x1,087
A14: 8 | B14: 2 | C14: ОН8_2 | D14: NA | E14: Tubifex costatus | F14: =VLOOKUP(E14,species_list!A$2:B$1194,2,FALSE) -> 828 | G14: 2 | H14: 0.003 | I14: Манылова | J14: Alexeeva_onega25.pdf(12), Poloskin-2_01.jpg, (0.5)
... A52: 16 | B52: 1 | C52: ОН16_1 | D52: NA | E52: Fabricia sabella | F52: =VLOOKUP(E52,species_list!A$2:B$1194,2,FALSE) -> 797 | G52: 1 | H52: 0.001 | I52: Манылова | J52: av-dop
A53: 16 | B53: 1 | C53: ОН16_1 | D53: NA | E53: Macoma balthica | F53: =VLOOKUP(E53,[1]species_list!A$2:B$1194,2,FALSE) -> 435 | G53: 59 | H53: 13.603 | I53: Манылова | J53: av-dop.pdf
A54: 17 | B54: 3 | C54: ОН17_3 | D54: NA | E54: Macoma balthica | F54: =VLOOKUP(E54,species_list!A$2:B$1194,2,FALSE) -> 435 | G54: 5 | H54: 0.614 | I54: Аристов | J54: Alexeeva_onega25.pdf(7-8), фауна с сита 0.5 просуммирована
A55: 17 | B55: 3 | C55: ОН17_3 | D55: NA | E55: Nephthys minuta | F55: =VLOOKUP(E55,species_list!A$2:B$1194,2,FALSE) -> 784 | G55: 1 | H55: 0.002 | I55: Аристов | J55: Alexeeva_onega25.pdf(7-8), фауна с сита 0.5 просуммирована
A56: 17 | B56: 3 | C56: ОН17_3 | D56: NA | E56: Eteone longa | F56: =VLOOKUP(E56,species_list!A$2:B$1194,2,FALSE) -> 709 | G56: 1 | H56: 0.001 | I56: Аристов | J56: Alexeeva_onega25.pdf(7-8), фауна с сита 0.5 просуммирована
A57: 17 | B57: 3 | C57: ОН17_3 | D57: NA | E57: Paranais litoralis | F57: =VLOOKUP(E57,species_list!A$2:B$1194,2,FALSE) -> 833 | G57: 5 | H57: 0.003 | I57: Аристов | J57: Alexeeva_onega25.pdf(7-8), фауна с сита 0.5 просуммирована
A58: 17 | B58: 3 | C58: ОН17_3 | D58: NA | E58: Tubifex costatus | F58: =VLOOKUP(E58,species_list!A$2:B$1194,2,FALSE) -> 828 | G58: 3 | H58: 0.002 | I58: Аристов | J58: Alexeeva_onega25.pdf(7-8), фауна с сита 0.5 просуммирована
A59: 17 | B59: 3 | C59: ОН17_3 | D59: NA | E59: Pygospio elegans | F59: =VLOOKUP(E59,species_list!A$2:B$1194,2,FALSE) -> 740 | G59: 2 | H59: 0.002 | I59: Аристов | J59: Alexeeva_onega25.pdf(7-8), фауна с сита 0.5 просуммирована
A60: 17 | B60: 3 | C60: ОН17_3 | D60: NA | E60: Hydrobia ventrosa | F60: =VLOOKUP(E60,species_list!A$2:B$1194,2,FALSE) -> 376 | G60: 28 | H60: 0.086 | I60: Аристов | J60: Alexeeva_onega25.pdf(7-8), фауна с сита 0.5 просуммирована, рассчетные значения, суммарно 720x2,051
A61: 17 | B61: 3 | C61: ОН17_3 | D61: NA | E61: Hydrobia ulvae | F61: =VLOOKUP(E61,species_list!A$2:B$1194,2,FALSE) -> 375 | G61: 693 | H61: 1.966 | I61: Аристов | J61: Alexeeva_onega25.pdf(7-8), фауна с сита 0.5 просуммирована, рассчетные значения, суммарно 720x2,051
A62: 17 | B62: 3 | C62: ОН17_3 | D62: NA | E62: Polychaeta | F62: =VLOOKUP(E62,species_list!A$2:B$1194,2,FALSE) -> 819 | G62: NA | H62: 0.001 | I62: Аристов | J62: Alexeeva_onega25.pdf(7-8), фауна с сита 0.5 просуммирована
A63: 17 | B63: 2 | C63: ОН17_2 | D63: NA | E63: Macoma balthica | F63: =VLOOKUP(E63,species_list!A$2:B$1194,2,FALSE) -> 435 | G63: 9 | H63: 2.847 | I63: Аристов | J63: Alexeeva_onega25.pdf(12), PoloskinA-1_01.jpg, фауна с сита 0.5 просуммирована
A64: 17 | B64: 2 | C64: ОН17_2 | D64: NA | E64: Pygospio elegans | F64: =VLOOKUP(E64,species_list!A$2:B$1194,2,FALSE) -> 740 | G64: 1 | H64: 0.002 | I64: Аристов | J64: Alexeeva_onega25.pdf(12), PoloskinA-1_01.jpg, фауна с сита 0.5 просуммирована
A65: 17 | B65: 2 | C65: ОН17_2 | D65: NA | E65: Paranais litoralis | F65: =VLOOKUP(E65,species_list!A$2:B$1194,2,FALSE) -> 833 | G65: 4 | H65: 0.004 | I65: Аристов | J65: Alexeeva_onega25.pdf(12), PoloskinA-1_01.jpg, фауна с сита 0.5 просуммирована
A66: 17 | B66: 2 | C66: ОН17_2 | D66: NA | E66: Tubifex costatus | F66: =VLOOKUP(E66,species_list!A$2:B$1194,2,FALSE) -> 828 | G66: 10 | H66: 0.014 | I66: Аристов | J66: Alexeeva_onega25.pdf(12), PoloskinA-1_01.jpg, фауна с сита 0.5 просуммирована
A67: 17 | B67: 2 | C67: ОН17_2 | D67: NA | E67: Hydrobia ulvae | F67: =VLOOKUP(E67,species_list!A$2:B$1194,2,FALSE) -> 375 | G67: 797 | H67: 2.34 | I67: Аристов | J67: Alexeeva_onega25.pdf(12-13), PoloskinA-1_01.jpg, фауна с сита 0.5 просуммирована, рассчетные значения, суммарно 713x2,025
A68: 17 | B68: 2 | C68: ОН17_2 | D68: NA | E68: Hydrobia ventrosa | F68: =VLOOKUP(E68,species_list!A$2:B$1194,2,FALSE) -> 376 | G68: 60 | H68: 0.146 | I68: Аристов | J68: Alexeeva_onega25.pdf(12-13), PoloskinA-1_01.jpg, фауна с сита 0.5 просуммирована, рассчетные значения, суммарно 713x2,025
A69: 17 | B69: 2 | C69: ОН17_2 | D69: NA | E69: Tubificoides benedeni | F69: =VLOOKUP(E69,species_list!A$2:B$1194,2,FALSE) -> 829 | G69: 6 | H69: 0.004 | I69: Аристов | J69: Alexeeva_onega25.pdf(12), PoloskinA-1_01.jpg, фауна с сита 0.5 просуммирована
A70: 18 | B70: 3 | C70: ОН18_3 | D70: NA | E70: Macoma balthica | F70: =VLOOKUP(E70,species_list!A$2:B$1194,2,FALSE) -> 435 | G70: 10 | H70: 1.53 | I70: Аристов | J70: Alexeeva_onega25.pdf(9-10), Poloskin-2_02.jpg, (0.5)
A71: 18 | B71: 3 | C71: ОН18_3 | D71: NA | E71: Arenicola marina | F71: =VLOOKUP(E71,species_list!A$2:B$1194,2,FALSE) -> 615 | G71: 1 | H71: 0.016 | I71: Аристов | J71: Alexeeva_onega25.pdf(9-10), Poloskin-2_02.jpg, (0.5)
A72: 18 | B72: 3 | C72: ОН18_3 | D72: NA | E72: Eteone longa | F72: =VLOOKUP(E72,species_list!A$2:B$1194,2,FALSE) -> 709 | G72: 4 | H72: 0.018 | I72: Аристов | J72: Alexeeva_onega25.pdf(9-10), Poloskin-2_02.jpg, (0.5)
A73: 18 | B73: 3 | C73: ОН18_3 | D73: NA | E73: Nephthys minuta | F73: =VLOOKUP(E73,species_list!A$2:B$1194,2,FALSE) -> 784 | G73: 1 | H73: 0.002 | I73: Аристов | J73: Alexeeva_onega25.pdf(9-10), Poloskin-2_02.jpg, (0.5)
A74: 18 | B74: 3 | C74: ОН18_3 | D74: NA | E74: Paranais litoralis | F74: =VLOOKUP(E74,species_list!A$2:B$1194,2,FALSE) -> 833 | G74: 5 | H74: 0.003 | I74: Аристов | J74: Alexeeva_onega25.pdf(9-10), Poloskin-2_02.jpg, (0.5)
... A85: 18 | B85: 2 | C85: ОН18_2 | D85: NA | E85: Eteone longa | F85: =VLOOKUP(E85,species_list!A$2:B$1194,2,FALSE) -> 709 | G85: 1 | H85: 0.002 | I85: Манылова | J85: Alexeeva_onega25.pdf(10-11), Poloskin-2_02.jpg, (0.5)
A86: 18 | B86: 2 | C86: ОН18_2 | D86: NA | E86: Hydrobia sp. | F86: =VLOOKUP(E86,species_list!A$2:B$1194,2,FALSE) -> #N/A | G86: 11 | H86: 0.005 | I86: Манылова | J86: Alexeeva_onega25.pdf(10-11), Poloskin-2_02.jpg, (0.5) | K86: сито 0.5
A87: 19 | B87: 1 | C87: ОН19_1 | D87: NA | E87: Nereis sp. | F87: =VLOOKUP(E87,species_list!A$2:B$1194,2,FALSE) -> 788 | G87: 1 | H87: 0.002 | I87: Манылова | J87: av-dop.pdf(17) | K87: сито 0.5
...

Sheet Hydrobia samples
I4: вводим сюда значения
J5: выборка 1
I6: Nобщ | J6: 3.627 | K6: выборка 2
I7: nP | J7: =0.527+0.007 -> 0.534
I8: nE | J8: 0.025
I11: NPрасс | J11: =SUM(J6:K8)*SUM(J7:K7)/SUM(J7:K8) -> 3.9987907
I12: NEрасс | J12: =SUM(J6:K8)*SUM(J8:K8)/SUM(J7:K8) -> 0.1872093
I13: Ntotal | J13: =ROUND(J11+J12,0) -> 4

Sheet size
A1: station | B1: sample | C1: station_name | D1: taxon_name | E1: size
A2: 8 | B2: 1 | C2: ОН8_1 | D2: Macoma balthica | E2: 10.5
A3: 8 | B3: 1 | C3: ОН8_1 | D3: Macoma balthica | E3: 12.6
A4: 8 | B4: 1 | C4: ОН8_1 | D4: Macoma balthica | E4: 10.4
A5: 8 | B5: 1 | C5: ОН8_1 | D5: Macoma balthica | E5: 13.1
A6: 8 | B6: 1 | C6: ОН8_1 | D6: Macoma balthica | E6: 13
A7: 8 | B7: 1 | C7: ОН8_1 | D7: Macoma balthica | E7: 12.6
A8: 8 | B8: 1 | C8: ОН8_1 | D8: Macoma balthica | E8: 12.6
A9: 8 | B9: 1 | C9: ОН8_1 | D9: Macoma balthica | E9: 12.9
A10: 8 | B10: 1 | C10: ОН8_1 | D10: Macoma balthica | E10: 12.1
A11: 8 | B11: 1 | C11: ОН8_1 | D11: Macoma balthica | E11: 10
A12: 8 | B12: 1 | C12: ОН8_1 | D12: Macoma balthica | E12: 13.3
A13: 8 | B13: 1 | C13: ОН8_1 | D13: Macoma balthica | E13: 11.5
... A288: 17 | B288: 1 | C288: ОН17_1 | D288: Mya arenaria | E288: 19.9

Sheet species_list
A1: taxon_name | B1: species_code | C1: worms | D1: worms_accepted
A2: Abietinaria abietina | B2: 1 | C2: 117870 | D2: 117870
A3: Sertularella sp. | B3: 10 | C3: 117233 | D3: 117233
A4: Cerianthus lloydi | B4: 100 | C4: 101010 | D4: 1674631
A5: Enteromorpha prolifera | B5: 1000 | C5: 145971 | D5: 234476
A6: Halosaccion ramentaceum | B6: 1001 | C6: 157367 | D6: 145770
A7: Ilea zostericola | B7: 1002 | C7: 500911 | D7: 1311362
A8: Chlorophyta | B8: 1003 | C8: 801 | D8: 801
A9: Monostroma grivelli | B9: 1004 | C9: 145940 | D9: 145940
A10: Ruppia maritima | B10: 1005 | C10: 234031 | D10: 234031
A11: Salicornia pojarkovi | B11: 1006 | C11: NA | D11: NA
A12: Tripolium vulgare | B12: 1007 | C12: 1213408 | D12: 1104085
A13: Triglochin maritimum | B13: 1008 | C13: 426006 | D13: 426006
A14: Zostera marina | B14: 1009 | C14: 495077 | D14: 145795
A15: Gersemia fruticosa | B15: 101 | C15: 156101 | D15: 156101
A16: Crangon allmanni | B16: 1010 | C16: 107551 | D16: 107551
A17: Hydrozoa | B17: 1011 | C17: 1337 | D17: 1337
A18: Bryozoa | B18: 1012 | C18: 146142 | D18: 146142
A19: Porifera | B19: 1013 | C19: 558 | D19: 558
A20: Amphipoda | B20: 1014 | C20: 1135 | D20: 1135
A21: Holothuroidea | B21: 1015 | C21: 123083 | D21: 123083
A22: Praxillura sp. | B22: 1016 | C22: 129361 | D22: 129361
A23: Scoloplos acutus | B23: 1017 | C23: 157563 | D23: 607421
... A90: Dorvelleidae | B90: 1081 | C90: 971 | D90: 133133
A91: Colus ebur | B91: 1082 | C91: NA | D91: 133133
A92: Dasychone sp. | B92: 1083 | C92: 155467 | D92: 134282
A93: Cossura sp. | B93: 1084 | C93: 129251 | D93: 132072
A94: Lumbrinereis sp. | B94: 1085 | C94: 203863 | D94: 103828
A95: Thyasira sp. | B95: 1086 | C95: 138552 | D95: 103862
A96: Flustra sp. | B96: 1087 | C96: 110911 | D96: 333162
A97: Scaphander sp. | B97: 1088 | C97: 137871 | D97: 151541
A98: Flabelligera sp. | B98: 1089 | C98: 129291 | D98: 1268
A99: Arrhis phyllonyx | B99: 109 | C99: 102870 | D99: 1271
A100: Portlandia lenticula | B100: 1090 | C100: 156360 | D100: 142516
A101: Brada inhabilis | B101: 1091 | C101: 130097 | D101: 144165
A102: Cylichna scalpta | B102: 1092 | C102: 423301 | D102: 151541
A103: Ampelisca gibba | B103: 1093 | C103: 101898 | D103: 101898
... A233: Andaniella pectinata | B233: 134 | C233: 103085 | D233: 254661
A234: Andaniella effloresans | B234: 135 | C234: NA | D234: NA
A235: Stegocephalidae | B235: 136 | C235: 101408 | D235: 101408
...
